{"trial_id": "00", "hyperparameters": {"space": [{"class_name": "Int", "config": {"name": "embedding_dim", "default": null, "conditions": [], "min_value": 32, "max_value": 128, "step": 32, "sampling": "linear"}}, {"class_name": "Int", "config": {"name": "num_lstm_layers", "default": null, "conditions": [], "min_value": 1, "max_value": 3, "step": 1, "sampling": "linear"}}, {"class_name": "Int", "config": {"name": "units_0", "default": null, "conditions": [], "min_value": 32, "max_value": 128, "step": 32, "sampling": "linear"}}, {"class_name": "Float", "config": {"name": "dropout_rate_0", "default": 0.1, "conditions": [], "min_value": 0.1, "max_value": 0.5, "step": 0.1, "sampling": "linear"}}, {"class_name": "Float", "config": {"name": "l2_lambda", "default": 0.001, "conditions": [], "min_value": 0.001, "max_value": 0.05, "step": null, "sampling": "log"}}, {"class_name": "Float", "config": {"name": "learning_rate", "default": 0.0001, "conditions": [], "min_value": 0.0001, "max_value": 0.01, "step": null, "sampling": "log"}}, {"class_name": "Int", "config": {"name": "units_1", "default": null, "conditions": [], "min_value": 32, "max_value": 128, "step": 32, "sampling": "linear"}}, {"class_name": "Float", "config": {"name": "dropout_rate_1", "default": 0.1, "conditions": [], "min_value": 0.1, "max_value": 0.5, "step": 0.1, "sampling": "linear"}}], "values": {"embedding_dim": 32, "num_lstm_layers": 2, "units_0": 96, "dropout_rate_0": 0.5, "l2_lambda": 0.001833490883368663, "learning_rate": 0.0001381941156312248, "units_1": 32, "dropout_rate_1": 0.1}}, "metrics": {"metrics": {}}, "score": null, "best_step": 0, "status": "FAILED", "message": "Traceback (most recent call last):\n  File \"c:\\Users\\ruizh\\anaconda3\\envs\\gpu_env\\lib\\site-packages\\keras_tuner\\src\\engine\\base_tuner.py\", line 273, in _try_run_and_update_trial\n    self._run_and_update_trial(trial, *fit_args, **fit_kwargs)\n  File \"c:\\Users\\ruizh\\anaconda3\\envs\\gpu_env\\lib\\site-packages\\keras_tuner\\src\\engine\\base_tuner.py\", line 238, in _run_and_update_trial\n    results = self.run_trial(trial, *fit_args, **fit_kwargs)\n  File \"c:\\Users\\ruizh\\anaconda3\\envs\\gpu_env\\lib\\site-packages\\keras_tuner\\src\\engine\\tuner.py\", line 314, in run_trial\n    obj_value = self._build_and_fit_model(trial, *args, **copied_kwargs)\n  File \"c:\\Users\\ruizh\\anaconda3\\envs\\gpu_env\\lib\\site-packages\\keras_tuner\\src\\engine\\tuner.py\", line 233, in _build_and_fit_model\n    results = self.hypermodel.fit(hp, model, *args, **kwargs)\n  File \"c:\\Users\\ruizh\\anaconda3\\envs\\gpu_env\\lib\\site-packages\\keras_tuner\\src\\engine\\hypermodel.py\", line 149, in fit\n    return model.fit(*args, **kwargs)\n  File \"c:\\Users\\ruizh\\anaconda3\\envs\\gpu_env\\lib\\site-packages\\keras\\utils\\traceback_utils.py\", line 70, in error_handler\n    raise e.with_traceback(filtered_tb) from None\n  File \"C:\\Users\\ruizh\\AppData\\Local\\Temp\\__autograph_generated_fileg2su09ez.py\", line 15, in tf__train_function\n    retval_ = ag__.converted_call(ag__.ld(step_function), (ag__.ld(self), ag__.ld(iterator)), None, fscope)\nValueError: in user code:\n\n    File \"c:\\Users\\ruizh\\anaconda3\\envs\\gpu_env\\lib\\site-packages\\keras\\engine\\training.py\", line 1160, in train_function  *\n        return step_function(self, iterator)\n    File \"c:\\Users\\ruizh\\anaconda3\\envs\\gpu_env\\lib\\site-packages\\keras\\engine\\training.py\", line 1146, in step_function  **\n        outputs = model.distribute_strategy.run(run_step, args=(data,))\n    File \"c:\\Users\\ruizh\\anaconda3\\envs\\gpu_env\\lib\\site-packages\\keras\\engine\\training.py\", line 1135, in run_step  **\n        outputs = model.train_step(data)\n    File \"c:\\Users\\ruizh\\anaconda3\\envs\\gpu_env\\lib\\site-packages\\keras\\engine\\training.py\", line 994, in train_step\n        loss = self.compute_loss(x, y, y_pred, sample_weight)\n    File \"c:\\Users\\ruizh\\anaconda3\\envs\\gpu_env\\lib\\site-packages\\keras\\engine\\training.py\", line 1052, in compute_loss\n        return self.compiled_loss(\n    File \"c:\\Users\\ruizh\\anaconda3\\envs\\gpu_env\\lib\\site-packages\\keras\\engine\\compile_utils.py\", line 265, in __call__\n        loss_value = loss_obj(y_t, y_p, sample_weight=sw)\n    File \"c:\\Users\\ruizh\\anaconda3\\envs\\gpu_env\\lib\\site-packages\\keras\\losses.py\", line 152, in __call__\n        losses = call_fn(y_true, y_pred)\n    File \"c:\\Users\\ruizh\\anaconda3\\envs\\gpu_env\\lib\\site-packages\\keras\\losses.py\", line 272, in call  **\n        return ag_fn(y_true, y_pred, **self._fn_kwargs)\n    File \"c:\\Users\\ruizh\\anaconda3\\envs\\gpu_env\\lib\\site-packages\\keras\\losses.py\", line 1990, in categorical_crossentropy\n        return backend.categorical_crossentropy(\n    File \"c:\\Users\\ruizh\\anaconda3\\envs\\gpu_env\\lib\\site-packages\\keras\\backend.py\", line 5529, in categorical_crossentropy\n        target.shape.assert_is_compatible_with(output.shape)\n\n    ValueError: Shapes (None, 1498) and (None, 1199) are incompatible\n\n"}